<?xml version="1.0" ?>
<!-- =================================================================================== -->
<!-- |    This document was autogenerated by xacro from ur.urdf.xacro                  | -->
<!-- |    EDITING THIS FILE BY HAND IS NOT RECOMMENDED                                 | -->
<!-- =================================================================================== -->
<robot name="ur5">
  <material name="LightGrey"><color rgba="0.7 0.7 0.7 0.2"/></material>
  <material name="LightBlue"><color rgba="0.7 0.7 0.8 0.2"/></material>
  <material name="LightGreen"><color rgba="0.7 0.8 0.7 0.2"/></material>
  <material name="LightRed"><color rgba="0.8 0.7 0.7 0.2"/></material>
  <link name="base_link">
    <inertial>
      <mass value="0.0"/>
      <origin rpy="0 0 0" xyz="0 0 0"/>
      <inertia ixx="0.0" ixy="0.0" ixz="0.0" iyy="0.0" iyz="0.0" izz="0.0"/>
    </inertial>
  </link>
  <link name="base_link_inertia">
    <visual>
      <origin rpy="0 0 3.141592653589793" xyz="0 0 0"/>
      <geometry>
        <mesh filename="meshes/ur5/visual/base.obj"/>
      </geometry>
      <material name="LightGrey"/>
    </visual>
    <collision>
      <origin rpy="0 0 3.141592653589793" xyz="0 0 0"/>
      <geometry>
        <mesh filename="meshes/ur5/collision/base.stl"/>
      </geometry>
    </collision>
    <inertial>
      <mass value="4.0"/>
      <origin rpy="0 0 0" xyz="0 0 0"/>
      <inertia ixx="0.00443333156" ixy="0.0" ixz="0.0" iyy="0.00443333156" iyz="0.0" izz="0.0072"/>
    </inertial>
  </link>
  <link name="shoulder_link">
    <visual>
      <origin rpy="0 0 3.141592653589793" xyz="0 0 0"/>
      <geometry>
        <mesh filename="meshes/ur5/visual/shoulder.obj"/>
      </geometry>
      <material name="LightBlue"/>
    </visual>
    <collision>
      <origin rpy="0 0 3.141592653589793" xyz="0 0 0"/>
      <geometry>
        <mesh filename="meshes/ur5/collision/shoulder.stl"/>
      </geometry>
    </collision>
    <inertial>
      <mass value="3.7"/>
      <origin rpy="0 0 0" xyz="0 0 0"/>
      <inertia ixx="0.014972352344389999" ixy="0.0" ixz="0.0" iyy="0.014972352344389999" iyz="0.0" izz="0.01040625"/>
    </inertial>
  </link>
  <link name="upper_arm_link">
    <visual>
      <origin rpy="1.5707963267948966 0 -1.5707963267948966" xyz="0 0 0.13585"/>
      <geometry>
        <mesh filename="meshes/ur5/visual/upperarm.obj"/>
      </geometry>
      <material name="LightGreen"/>
    </visual>
    <collision>
      <origin rpy="1.5707963267948966 0 -1.5707963267948966" xyz="0 0 0.13585"/>
      <geometry>
        <mesh filename="meshes/ur5/collision/upperarm.stl"/>
      </geometry>
    </collision>
    <inertial>
      <mass value="8.393"/>
      <origin rpy="0 1.5707963267948966 0" xyz="-0.2125 0.0 0.136"/>
      <inertia ixx="0.1338857818623325" ixy="0.0" ixz="0.0" iyy="0.1338857818623325" iyz="0.0" izz="0.0151074"/>
    </inertial>
  </link>
  <link name="forearm_link">
    <visual>
      <origin rpy="1.5707963267948966 0 -1.5707963267948966" xyz="0 0 0.0165"/>
      <geometry>
        <mesh filename="meshes/ur5/visual/forearm.obj"/>
      </geometry>
      <material name="LightRed"/>
    </visual>
    <collision>
      <origin rpy="1.5707963267948966 0 -1.5707963267948966" xyz="0 0 0.0165"/>
      <geometry>
        <mesh filename="meshes/ur5/collision/forearm.stl"/>
      </geometry>
    </collision>
    <inertial>
      <mass value="2.275"/>
      <origin rpy="0 1.5707963267948966 0" xyz="-0.196125 0.0 0.0165"/>
      <inertia ixx="0.03121679102890359" ixy="0.0" ixz="0.0" iyy="0.03121679102890359" iyz="0.0" izz="0.004095"/>
    </inertial>
  </link>
  <link name="wrist_1_link">
    <visual>
      <origin rpy="1.5707963267948966 0 0" xyz="0 0 -0.093"/>
      <geometry>
        <mesh filename="meshes/ur5/visual/wrist1.obj"/>
      </geometry>
      <material name="LightGrey"/>
    </visual>
    <collision>
      <origin rpy="1.5707963267948966 0 0" xyz="0 0 -0.093"/>
      <geometry>
        <mesh filename="meshes/ur5/collision/wrist1.stl"/>
      </geometry>
    </collision>
    <inertial>
      <mass value="1.219"/>
      <origin rpy="0 0 0" xyz="0 0 0"/>
      <inertia ixx="0.0020138887777775" ixy="0.0" ixz="0.0" iyy="0.0020138887777775" iyz="0.0" izz="0.0021942"/>
    </inertial>
  </link>
  <link name="wrist_2_link">
    <visual>
      <origin rpy="0 0 0" xyz="0 0 -0.095"/>
      <geometry>
        <mesh filename="meshes/ur5/visual/wrist2.obj"/>
      </geometry>
      <material name="LightBlue"/>
    </visual>
    <collision>
      <origin rpy="0 0 0" xyz="0 0 -0.095"/>
      <geometry>
        <mesh filename="meshes/ur5/collision/wrist2.stl"/>
      </geometry>
    </collision>
    <inertial>
      <mass value="1.219"/>
      <origin rpy="0 0 0" xyz="0 0 0"/>
      <inertia ixx="0.0018310388509175" ixy="0.0" ixz="0.0" iyy="0.0018310388509175" iyz="0.0" izz="0.0021942"/>
    </inertial>
  </link>
  <link name="wrist_3_link">   <!--Solve iK for this link.-->
    <visual>
      <origin rpy="1.5707963267948966 0 0" xyz="0 0 -0.0818"/>
      <geometry>
        <mesh filename="meshes/ur5/visual/wrist3.obj"/>
      </geometry>
      <material name="LightGreen"/>
    </visual>
    <collision>
      <origin rpy="1.5707963267948966 0 0" xyz="0 0 -0.0818"/>
      <geometry>
        <mesh filename="meshes/ur5/collision/wrist3.stl"/>
      </geometry>
    </collision>
    <inertial>
      <mass value="0.1879"/>
      <origin rpy="0 0 0" xyz="0.0 0.0 -0.01525"/>
      <inertia ixx="8.062472608343e-05" ixy="0.0" ixz="0.0" iyy="8.062472608343e-05" iyz="0.0" izz="0.0001321171875"/>
    </inertial>
  </link>
  <!--Suction Gripper-->
  <material name="DarkGrey"><color rgba="0.2 0.2 0.2 0.2"/></material>
  <material name="Blue"><color rgba="0.18039216, 0.50588235, 0.77254902 0.2"/></material>
  <link name="suctionBaseLink">
    <contact>
      <lateral_friction value="1.0"/>
      <rolling_friction value="0.0001"/>
      <inertia_scaling value="3.0"/>
    </contact>
    <inertial>
      <origin rpy="0 0 0" xyz="0 0 0.0"/>
       <mass value=".1"/>
       <inertia ixx="1" ixy="0" ixz="0" iyy="1" iyz="0" izz="1"/>
    </inertial>
    <visual>
      <origin rpy="0 0 0" xyz="0 0 0.0"/>
      <geometry>
        <mesh filename="suction/base.obj" scale="0.001 0.001 0.001"/>
      </geometry>
      <material name="DarkGrey"/>
    </visual>
    <collision>
      <origin rpy="0 0 0" xyz="0 0 0.0"/>
      <geometry>
        <mesh filename="suction/base.obj" scale="0.001 0.001 0.001"/>
      </geometry>
    </collision>
  </link>
  <link name="EPick">
    <contact>
      <lateral_friction value="1.0"/>
      <rolling_friction value="0.0001"/>
      <inertia_scaling value="3.0"/>
    </contact>
    <inertial>
      <origin rpy="0 0 0" xyz="0 0 0"/>
       <mass value=".1"/>
       <inertia ixx="1" ixy="0" ixz="0" iyy="1" iyz="0" izz="1"/>
    </inertial>
    <visual>
      <origin rpy="1.57079 0 0" xyz="0 0 0"/>
      <geometry>
        <mesh filename="suction/EPick.obj" scale="0.001 0.001 0.001"/>
      </geometry>
      <material name="DarkGrey"/>
    </visual>
    <collision>
      <origin rpy="1.57079 0 0" xyz="0 0 0"/>
      <geometry>
        <mesh filename="suction/EPick_vhacd.obj" scale="0.001 0.001 0.001"/>
      </geometry>
    </collision>
  </link>
  <link name="headLink">
    <contact>
      <lateral_friction value="1.0"/>
      <rolling_friction value="0.0001"/>
      <inertia_scaling value="3.0"/>
    </contact>
    <inertial>
      <origin rpy="0 0 0" xyz="0 0 0"/>
       <mass value=".1"/>
       <inertia ixx="1" ixy="0" ixz="0" iyy="1" iyz="0" izz="1"/>
    </inertial>
    <visual>
      <origin rpy="0 0 0" xyz="0 0 0"/>
      <geometry>
        <mesh filename="suction/head.obj" scale="0.001 0.001 0.001"/>
      </geometry>
      <material name="DarkGrey"/>
    </visual>
    <collision>
      <origin rpy="0 0 0" xyz="0 0 0"/>
      <geometry>
        <mesh filename="suction/head.obj" scale="0.002 0.002 0.001"/>
      </geometry>
    </collision>
  </link>
  <link name="tipLink">
    <contact>
      <lateral_friction value="1.0"/>
      <rolling_friction value="0.0001"/>
      <inertia_scaling value="3.0"/>
      <restitution value="0.2"/>
    </contact>
    <inertial>
      <origin rpy="0 0 0" xyz="0 0 0"/>
       <mass value=".1"/>
       <inertia ixx="1" ixy="0" ixz="0" iyy="1" iyz="0" izz="1"/>
    </inertial>
    <visual>
      <origin rpy="0 0 0" xyz="0 0 0"/>
      <geometry>
        <mesh filename="suction/tip.obj" scale="0.002 0.002 0.001"/>
      </geometry>
      <material name="Blue"/>
    </visual>
  </link>
  <link name="tipCollision1">
    <contact>
      <lateral_friction value="1.0"/>
      <rolling_friction value="0.0001"/>
      <inertia_scaling value="3.0"/>
      <restitution value="0.2"/>
    </contact>
    <inertial>
      <origin rpy="0 0 0" xyz="0 0 0"/>
        <mass value=".0001"/>
        <inertia ixx="0.0001" ixy="0" ixz="0" iyy="0.0001" iyz="0" izz="0.0001"/>
    </inertial>
    <visual>
      <origin rpy="0 0 0" xyz="0 0 0"/>
      <geometry>
        <cylinder length="0.005" radius="0.001"/>
      </geometry>      
      <material name="Blue"/>
    </visual>
    <collision>
      <origin rpy="0 0 0" xyz="0 0 0"/>
      <geometry>
        <cylinder length="0.005" radius="0.001"/>
      </geometry>
    </collision>
  </link>
  <link name="tipCollision3">
    <contact>
      <lateral_friction value="1.0"/>
      <rolling_friction value="0.0001"/>
      <inertia_scaling value="3.0"/>
      <restitution value="0.2"/>
    </contact>
    <inertial>
      <origin rpy="0 0 0" xyz="0 0 0"/>
        <mass value=".0001"/>
        <inertia ixx="0.0001" ixy="0" ixz="0" iyy="0.0001" iyz="0" izz="0.0001"/>
    </inertial>
    <visual>
      <origin rpy="0 0 0" xyz="0 0 0"/>
      <geometry>
        <cylinder length="0.005" radius="0.001"/>
      </geometry>
      <material name="Blue"/>
    </visual>
    <collision>
      <origin rpy="0 0 0" xyz="0 0 0"/>
      <geometry>
        <cylinder length="0.005" radius="0.001"/>
      </geometry>
    </collision>
  </link>
  <link name="tipCollision5">
    <contact>
      <lateral_friction value="1.0"/>
      <rolling_friction value="0.0001"/>
      <inertia_scaling value="3.0"/>
      <restitution value="0.2"/>
    </contact>
    <inertial>
      <origin rpy="0 0 0" xyz="0 0 0"/>
        <mass value=".0001"/>
        <inertia ixx="0.0001" ixy="0" ixz="0" iyy="0.0001" iyz="0" izz="0.0001"/>
    </inertial>
    <visual>
      <origin rpy="0 0 0" xyz="0 0 0"/>
      <geometry>
        <cylinder length="0.005" radius="0.001"/>
      </geometry>
      <material name="Blue"/>
    </visual>
    <collision>
      <origin rpy="0 0 0" xyz="0 0 0"/>
      <geometry>
        <cylinder length="0.005" radius="0.001"/>
      </geometry>
    </collision>
  </link>
  <link name="tipCollision7">
    <contact>
      <lateral_friction value="1.0"/>
      <rolling_friction value="0.0001"/>
      <inertia_scaling value="3.0"/>
      <restitution value="0.2"/>
    </contact>
    <inertial>
      <origin rpy="0 0 0" xyz="0 0 0"/>
        <mass value=".0001"/>
        <inertia ixx="0.0001" ixy="0" ixz="0" iyy="0.0001" iyz="0" izz="0.0001"/>
    </inertial>
    <visual>
      <origin rpy="0 0 0" xyz="0 0 0"/>
      <geometry>
        <cylinder length="0.005" radius="0.001"/>
      </geometry>
      <material name="Blue"/>
    </visual>
    <collision>
      <origin rpy="0 0 0" xyz="0 0 0"/>
      <geometry>
        <cylinder length="0.005" radius="0.001"/>
      </geometry>
    </collision>
  </link>
  <!-- joints - main serial chain -->
  <joint name="base_link-base_link_inertia" type="fixed">     <!--Joint 0-->
    <parent link="base_link"/>
    <child link="base_link_inertia"/>
    <!-- 'base_link' is REP-103 aligned (so X+ forward), while the internal
           frames of the robot/controller have X+ pointing backwards.
           Use the joint between 'base_link' and 'base_link_inertia' (a dummy
           link/frame) to introduce the necessary rotation over Z (of pi rad).
      -->
    <origin rpy="0 0 3.141592653589793" xyz="0 0 0"/>
  </joint>
  <joint name="shoulder_pan_joint" type="revolute">           <!--Joint 1-->
    <parent link="base_link_inertia"/>
    <child link="shoulder_link"/>
    <origin rpy="0 0 0" xyz="0 0 0.089159"/>
    <axis xyz="0 0 1"/>
    <limit effort="150.0" lower="-6.283185307179586" upper="6.283185307179586" velocity="3.141592653589793"/>
    <dynamics damping="0" friction="0"/>
  </joint>
  <joint name="shoulder_lift_joint" type="revolute">          <!--Joint 2-->
    <parent link="shoulder_link"/>
    <child link="upper_arm_link"/>
    <origin rpy="1.570796327 0 0" xyz="0 0 0"/>
    <axis xyz="0 0 1"/>
    <limit effort="150.0" lower="-6.283185307179586" upper="6.283185307179586" velocity="3.141592653589793"/>
    <dynamics damping="0" friction="0"/>
  </joint>
  <joint name="elbow_joint" type="revolute">                  <!--Joint 3-->
    <parent link="upper_arm_link"/>
    <child link="forearm_link"/>
    <origin rpy="0 0 0" xyz="-0.425 0 0"/>
    <axis xyz="0 0 1"/>
    <limit effort="150.0" lower="-3.141592653589793" upper="3.141592653589793" velocity="3.141592653589793"/>
    <dynamics damping="0" friction="0"/>
  </joint>
  <joint name="wrist_1_joint" type="revolute">                <!--Joint 4-->
    <parent link="forearm_link"/>
    <child link="wrist_1_link"/>
    <origin rpy="0 0 0" xyz="-0.39225 0 0.10915"/>
    <axis xyz="0 0 1"/>
    <limit effort="28.0" lower="-6.283185307179586" upper="6.283185307179586" velocity="3.141592653589793"/>
    <dynamics damping="0" friction="0"/>
  </joint>
  <joint name="wrist_2_joint" type="revolute">                <!--Joint 5-->
    <parent link="wrist_1_link"/>
    <child link="wrist_2_link"/>
    <origin rpy="1.570796327 0 0" xyz="0 -0.09465 -1.941303950897609e-11"/>
    <axis xyz="0 0 1"/>
    <limit effort="28.0" lower="-6.283185307179586" upper="6.283185307179586" velocity="3.141592653589793"/>
    <dynamics damping="0" friction="0"/>
  </joint>
  <joint name="wrist_3_joint" type="revolute">                <!--Joint 6, solve IK for this joint.--> 
    <parent link="wrist_2_link"/>
    <child link="wrist_3_link"/>
    <origin rpy="1.570796326589793 3.141592653589793 3.141592653589793" xyz="0 0.0823 -1.688001216681175e-11"/>
    <axis xyz="0 0 1"/>
    <limit effort="28.0" lower="-6.283185307179586" upper="6.283185307179586" velocity="3.141592653589793"/>
    <dynamics damping="0" friction="0"/>
  </joint>
  <!-- Gripper joints -->
  <joint name="ee_fixed_joint" type="fixed">                  <!--Joint 7-->
    <parent link="wrist_3_link"/>
    <child link="suctionBaseLink"/>
    <origin rpy="0.0 0.0 0.0" xyz="0.0 0.0 0.0"/> 
  </joint>
  <joint name="baseLink-midLink" type="fixed">                <!--Joint 8-->
    <origin rpy="0 0 0" xyz="0 0 0.115"/>
    <parent link="suctionBaseLink"/>
    <child link="EPick"/>
  </joint>
  <joint name="headJoint" type="fixed">                       <!--Joint 9-->
    <origin rpy="0 0 3.1415926" xyz="0 0 0.0"/>
    <parent link="EPick"/>
    <child link="headLink"/>
  </joint>
  <joint name="tipJoint" type="fixed">                        <!--Joint 10-->
    <parent link="headLink"/>
    <child link="tipLink"/>
    <origin rpy="0.0 0.0 0.0" xyz="0.0 0.0 0.015"/>
    <axis xyz="0 0 1"/>
    <limit effort="150.0" lower="-6.28318530718" upper="6.28318530718" velocity="3.15"/>
    <dynamics damping="10.0" friction="0.0"/>
  </joint>
  <joint name="tipCollision1Joint" type="fixed">                        <!--Joint 11-->
    <parent link="tipLink"/>
    <child link="tipCollision1"/>
    <origin rpy="0.0 0.0 0.0" xyz="0.016 0.0 0.015"/>
    <axis xyz="0 0 1"/>
  </joint>
  <joint name="tipCollision3Joint" type="fixed">                        <!--Joint 13-->
    <parent link="tipLink"/>
    <child link="tipCollision3"/>
    <origin rpy="0.0 0.0 0.0" xyz="0.0 0.016 0.015"/>
    <axis xyz="0 0 1"/>
  </joint>
  <joint name="tipCollision5Joint" type="fixed">                        <!--Joint 15-->
    <parent link="tipLink"/>
    <child link="tipCollision5"/>
    <origin rpy="0.0 0.0 0.0" xyz="-0.016 0.0 0.015"/>
    <axis xyz="0 0 1"/>
  </joint>
  <joint name="tipCollision7Joint" type="fixed">                        <!--Joint 17-->
    <parent link="tipLink"/>
    <child link="tipCollision7"/>
    <origin rpy="0.0 0.0 0.0" xyz="0.0 -0.016 0.015"/>
    <axis xyz="0 0 1"/>
  </joint>
</robot>
